2025-10-20 20:50:52,611 [WARNING] Database not available, running without DB: (pyodbc.OperationalError) ('08001', '[08001] [Microsoft][ODBC Driver 17 for SQL Server]Named Pipes Provider: Could not open a connection to SQL Server [53].  (53) (SQLDriverConnect); [08001] [Microsoft][ODBC Driver 17 for SQL Server]Login timeout expired (0); [08001] [Microsoft][ODBC Driver 17 for SQL Server]A network-related or instance-specific error has occurred while establishing a connection to SQL Server. Server is not found or not accessible. Check if instance name is correct and if SQL Server is configured to allow remote connections. For more information see SQL Server Books Online. (53)')
(Background on this error at: https://sqlalche.me/e/20/e3q8)
2025-10-20 20:50:52,685 [INFO] [31m[1mWARNING: This is a development server. Do not use it in a production deployment. Use a production WSGI server instead.[0m
 * Running on all addresses (0.0.0.0)
 * Running on http://127.0.0.1:5000
 * Running on http://10.231.16.170:5000
2025-10-20 20:50:52,685 [INFO] [33mPress CTRL+C to quit[0m
2025-10-20 20:50:52,687 [INFO]  * Restarting with stat
2025-10-20 20:51:09,659 [WARNING] Database not available, running without DB: (pyodbc.OperationalError) ('08001', '[08001] [Microsoft][ODBC Driver 17 for SQL Server]Named Pipes Provider: Could not open a connection to SQL Server [53].  (53) (SQLDriverConnect); [08001] [Microsoft][ODBC Driver 17 for SQL Server]Login timeout expired (0); [08001] [Microsoft][ODBC Driver 17 for SQL Server]A network-related or instance-specific error has occurred while establishing a connection to SQL Server. Server is not found or not accessible. Check if instance name is correct and if SQL Server is configured to allow remote connections. For more information see SQL Server Books Online. (53)')
(Background on this error at: https://sqlalche.me/e/20/e3q8)
2025-10-20 20:51:09,744 [WARNING]  * Debugger is active!
2025-10-20 20:51:09,759 [INFO]  * Debugger PIN: 143-791-316
2025-10-20 20:51:34,199 [INFO] Generated new Zoom token, expires in 3599 seconds
2025-10-20 20:51:37,287 [ERROR] Error fetching users: 403 Client Error: Forbidden for url: https://api.zoom.us/v2/phone/users?page_size=100&page_number=1
2025-10-20 20:51:37,332 [INFO] 127.0.0.1 - - [20/Oct/2025 20:51:37] "GET / HTTP/1.1" 200 -
2025-10-20 20:51:37,603 [INFO] 127.0.0.1 - - [20/Oct/2025 20:51:37] "[33mGET /favicon.ico HTTP/1.1[0m" 404 -
2025-10-20 20:51:40,945 [INFO] 127.0.0.1 - - [20/Oct/2025 20:51:40] "[35m[1mGET /refresh_users HTTP/1.1[0m" 500 -
2025-10-20 20:52:40,525 [INFO] 127.0.0.1 - - [20/Oct/2025 20:52:40] "[35m[1mPOST /single_update HTTP/1.1[0m" 500 -
2025-10-21 00:47:59,376 [INFO] [31m[1mWARNING: This is a development server. Do not use it in a production deployment. Use a production WSGI server instead.[0m
 * Running on all addresses (0.0.0.0)
 * Running on http://127.0.0.1:5000
 * Running on http://10.231.16.170:5000
2025-10-21 00:47:59,377 [INFO] [33mPress CTRL+C to quit[0m
2025-10-21 00:47:59,381 [INFO]  * Restarting with stat
2025-10-21 00:48:01,382 [WARNING]  * Debugger is active!
2025-10-21 00:48:01,393 [INFO]  * Debugger PIN: 143-791-316
2025-10-21 00:48:14,571 [INFO] Generated new Zoom token; expires_in=3599
2025-10-21 00:48:16,252 [ERROR] index list_phone_users error: 403 Client Error: Forbidden for url: https://api.zoom.us/v2/phone/users?page_size=100&page_number=1
Traceback (most recent call last):
  File "C:\Users\sdas2\Downloads\Old_Zoom_Phone_Caller_ID_Manager\app.py", line 297, in index
    users = cached_phone_users()
            ^^^^^^^^^^^^^^^^^^^^
  File "C:\Users\sdas2\Downloads\Old_Zoom_Phone_Caller_ID_Manager\app.py", line 289, in cached_phone_users
    USERS_CACHE["data"] = list_phone_users()
                          ^^^^^^^^^^^^^^^^^^
  File "C:\Users\sdas2\Downloads\Old_Zoom_Phone_Caller_ID_Manager\app.py", line 99, in list_phone_users
    resp.raise_for_status()
  File "C:\Users\sdas2\Downloads\Old_Zoom_Phone_Caller_ID_Manager\venv\Lib\site-packages\requests\models.py", line 1026, in raise_for_status
    raise HTTPError(http_error_msg, response=self)
requests.exceptions.HTTPError: 403 Client Error: Forbidden for url: https://api.zoom.us/v2/phone/users?page_size=100&page_number=1
2025-10-21 00:48:16,282 [INFO] 127.0.0.1 - - [21/Oct/2025 00:48:16] "GET / HTTP/1.1" 200 -
2025-10-21 00:48:18,903 [ERROR] refresh_users error: 403 Client Error: Forbidden for url: https://api.zoom.us/v2/phone/users?page_size=100&page_number=1
Traceback (most recent call last):
  File "C:\Users\sdas2\Downloads\Old_Zoom_Phone_Caller_ID_Manager\app.py", line 306, in refresh_users_route
    users = cached_phone_users(force_refresh=True)
            ^^^^^^^^^^^^^^^^^^^^^^^^^^^^^^^^^^^^^^
  File "C:\Users\sdas2\Downloads\Old_Zoom_Phone_Caller_ID_Manager\app.py", line 289, in cached_phone_users
    USERS_CACHE["data"] = list_phone_users()
                          ^^^^^^^^^^^^^^^^^^
  File "C:\Users\sdas2\Downloads\Old_Zoom_Phone_Caller_ID_Manager\app.py", line 99, in list_phone_users
    resp.raise_for_status()
  File "C:\Users\sdas2\Downloads\Old_Zoom_Phone_Caller_ID_Manager\venv\Lib\site-packages\requests\models.py", line 1026, in raise_for_status
    raise HTTPError(http_error_msg, response=self)
requests.exceptions.HTTPError: 403 Client Error: Forbidden for url: https://api.zoom.us/v2/phone/users?page_size=100&page_number=1
2025-10-21 00:48:18,908 [INFO] 127.0.0.1 - - [21/Oct/2025 00:48:18] "[35m[1mGET /refresh_users HTTP/1.1[0m" 500 -
2025-10-21 00:48:43,121 [INFO] 127.0.0.1 - - [21/Oct/2025 00:48:43] "[35m[1mPOST /single_update HTTP/1.1[0m" 500 -
